<mujoco model="lbr4">
  <compiler angle="radian" meshdir="./meshes/" />
  <size njmax="500" nconmax="100" />
  <asset>
    <mesh name="base" file="base.stl" />
    <mesh name="kuka_mount" file="kuka_mount.stl" />
    <mesh name="allegro_mount" file="allegro_mount.stl" />
  </asset>

  <worldbody>
    <body name="table_link" pos="0 0 0.295">
      <inertial pos="0 0 0" mass="200" diaginertia="0.1 0.1 0.1" />
      <geom size="0.305 0.45625 0.295" type="box" rgba="0.823529 0.666667 0.470588 1" />
      <body name="base_link" pos="0 0 0.305" quat="0.707388 0 0 0.706825">
        <inertial pos="0.0015 -0.0013135 -0.000496533" quat="-1.63027e-05 0.707107 -1.63027e-05 0.707107" mass="1.60945" diaginertia="0.02334 0.0118089 0.0116229" />
        <geom type="mesh" rgba="0.2 0.2 0.2 1" mesh="base" />
        <body name="lbr4_0_link" pos="0.0015 -0.0015 0.009">
          <inertial pos="0.00997877 -0.000481699 -0.254855" quat="-0.293322 0.633117 -0.0717834 0.712722" mass="1.5" diaginertia="0.00863586 0.00845152 0.00805113" />
          <geom size="0.08 0.0515" pos="0 0 0.0515" type="cylinder" rgba="1 0.423529 0.196078 1" />
          <body name="lbr4_1_link" pos="0 0 0.103">
            <inertial pos="2.1827e-05 -0.0216238 -0.0791517" quat="0.99254 0.119381 0.0056098 0.0241076" mass="1.5" diaginertia="0.0129545 0.0128178 0.00442073" />
            <joint name="lbr4_j0" pos="0 0 0" axis="0 0 1" limited="true" range="-2.879 2.879" />
            <geom size="0.06 0.08 0.135" pos="0 0.017 0.135" type="box" rgba="1 0.423529 0.196078 1" />
            <body name="lbr4_2_link" pos="0 -0.002 0.208">
              <inertial pos="-0.00100971 0.0284785 0.0820336" quat="0.991568 0.12607 -0.00469624 0.0296182" mass="1.5" diaginertia="0.013295 0.0131003 0.00446574" />
              <joint name="lbr4_j1" pos="0 0 0" axis="0 -1 0" limited="true" range="-2.007 2.007" />
              <geom size="0.06 0.08 0.135" pos="0 -0.017 0.075" type="box" rgba="1 0.423529 0.196078 1" />
              <body name="lbr4_3_link" pos="0 0 0.1915">
                <inertial pos="-0.000685125 0.0227876 -0.0788065" quat="0.706358 -0.0808672 0.0682921 0.699896" mass="1.5" diaginertia="0.0128011 0.0127764 0.00436274" />
                <joint name="lbr4_j2" pos="0 0 0" axis="0 0 1" limited="true" range="-2.879 2.879" />
                <geom size="0.06 0.08 0.135" pos="0 -0.017 0.135" type="box" rgba="1 0.423529 0.196078 1" />
                <body name="lbr4_4_link" pos="0 0.002 0.2085">
                  <inertial pos="-0.000251206 0.0270405 0.0825999" quat="0.991344 0.129174 0.00191488 0.0234177" mass="1.5" diaginertia="0.0132277 0.0130734 0.00439978" />
                  <joint name="lbr4_j3" pos="0 0 0" axis="0 1 0" limited="true" range="-2.007 2.007" />
                  <geom size="0.06 0.08 0.135" pos="0 0.017 0.075" type="box" rgba="1 0.423529 0.196078 1" />
                  <body name="lbr4_5_link" pos="0 0 0.1915">
                    <inertial pos="-7.29517e-05 0.0343006 -0.0828364" quat="0.690864 -0.149244 0.131148 0.69515" mass="1.5" diaginertia="0.012471 0.0124408 0.00438006" />
                    <joint name="lbr4_j4" pos="0 0 0" axis="0 0 1" limited="true" range="-2.879 2.879" />
                    <geom size="0.06 0.08 0.135" pos="0 0.017 0.13" type="box" rgba="1 0.423529 0.196078 1" />
                    <body name="lbr4_6_link" pos="0 0 0.199">
                      <inertial pos="0.00332658 -0.000250606 0.000625058" quat="0.603426 0.403302 0.36782 0.58132" mass="0.75" diaginertia="0.00298257 0.00296893 0.00284169" />
                      <joint name="lbr4_j5" pos="0 0 0" axis="0 -1 0" limited="true" range="-2.007 2.007" />
                      <geom size="0.078" rgba="0.3 0.3 0.3 1" />
                      <body name="lbr4_7_link" pos="0 0 0.078">
                        <inertial pos="-1.05089e-05 0.000493915 0.0625078" quat="0.218059 0.669521 -0.214663 0.67684" mass="0.075" diaginertia="9.68983e-05 5.84472e-05 5.81503e-05" />
                        <joint name="lbr4_j6" pos="0 0 0" axis="0 0 1" limited="true" range="-2.879 2.879" />
                        <geom size="0.025 0.025 0.005" type="box" rgba="0.2 0.2 0.2 1" />
                        <body name="lbr4_mount" pos="0.0009 0.0009 0.015" quat="0 -1 0 0">
                          <inertial pos="0 0 0" quat="0.5 0.5 -0.5 0.5" mass="0.199" diaginertia="0.000201488 0.000104475 0.000104475" />
                          <geom type="mesh" rgba="0.2 0.2 0.2 1" mesh="kuka_mount" />
                          <body name="allegro_mount" pos="-0.0425 0 -0.0425" quat="0.707388 0 0.706825 0">
                            <inertial pos="0 0 0" mass="0.05" diaginertia="0.0001 0.0001 0.0001" />
                            <geom pos="-0.0425 -0.0425 0" type="mesh" rgba="0.2 0.2 0.2 1" mesh="allegro_mount" />
                            <body name="palm_link" pos="0.065 0 0.0275" quat="0.707388 0 0.706825 0">
                              <inertial pos="0 0 0" mass="0.4154" diaginertia="0.0001 0.0001 0.0001" />
                              <geom size="0.0204 0.0565 0.0475" pos="-0.0093 0 -0.0475" type="box" rgba="0.2 0.2 0.2 1" />
                              <body name="index_finger_0" pos="0 0.0435 -0.001542" quat="0.999048 -0.0436194 0 0">
                                <inertial pos="0 0 0" quat="0.707107 0.707107 0 0" mass="0.0119" diaginertia="1.01667e-06 1.01667e-06 6.47677e-07" />
                                <joint name="index_joint_0" pos="0 0 0" axis="0 0 1" limited="true" range="-0.59 0.57" />
                                <geom size="0.0098 0.01375 0.0082" pos="0 0 0.0082" type="box" rgba="0.2 0.2 0.2 1" />
                                <body name="index_finger_1" pos="0 0 0.0164">
                                  <inertial pos="0 0 0" quat="0.702596 0.559386 -0.178354 0.402039" mass="0.065" diaginertia="6.12799e-05 6.12799e-05 6.12799e-05" />
                                  <joint name="index_joint_1" pos="0 0 0" axis="0 1 0" limited="true" range="-0.296 1.71" />
                                  <geom size="0.0098 0.01375 0.027" pos="0 0 0.027" type="box" rgba="0.2 0.2 0.2 1" />
                                  <body name="index_finger_2" pos="0 0 0.054">
                                    <inertial pos="0 0 0" quat="0.719796 0.528175 -0.157463 0.422055" mass="0.0355" diaginertia="2.20969e-05 2.20969e-05 2.20969e-05" />
                                    <joint name="index_joint_2" pos="0 0 0" axis="0 1 0" limited="true" range="-0.274 1.809" />
                                    <geom size="0.0098 0.01375 0.0192" pos="0 0 0.0192" type="box" rgba="0.2 0.2 0.2 1" />
                                    <body name="index_finger_3" pos="0 0 0.0384">
                                      <inertial pos="0 0 0" quat="0.760448 0.456478 -0.161222 0.432844" mass="0.0096" diaginertia="4.3506e-06 4.3506e-06 4.3506e-06" />
                                      <joint name="index_joint_3" pos="0 0 0" axis="0 1 0" limited="true" range="-0.327 1.718" />
                                      <geom size="0.0098 0.01375 0.01335" pos="0 0 0.01335" type="box" rgba="0.2 0.2 0.2 1" />
                                      <body name="index_tip" pos="0 0 0.0267">
                                        <inertial pos="0 0 0" mass="0.0168" diaginertia="9.68e-07 9.68e-07 9.68e-07" />
                                        <geom size="0.012" rgba="1 1 1 1" />
                                      </body>
                                    </body>
                                  </body>
                                </body>
                              </body>
                              <body name="middle_finger_0" pos="0 0 0.0007">
                                <inertial pos="0 0 0" quat="0.707107 0.707107 0 0" mass="0.0119" diaginertia="1.01667e-06 1.01667e-06 6.47677e-07" />
                                <joint name="middle_joint_0" pos="0 0 0" axis="0 0 1" limited="true" range="-0.59 0.57" />
                                <geom size="0.0098 0.01375 0.0082" pos="0 0 0.0082" type="box" rgba="0.2 0.2 0.2 1" />
                                <body name="middle_finger_1" pos="0 0 0.0164">
                                  <inertial pos="0 0 0" quat="0.702596 0.559386 -0.178354 0.402039" mass="0.065" diaginertia="6.12799e-05 6.12799e-05 6.12799e-05" />
                                  <joint name="middle_joint_1" pos="0 0 0" axis="0 1 0" limited="true" range="-0.296 1.71" />
                                  <geom size="0.0098 0.01375 0.027" pos="0 0 0.027" type="box" rgba="0.2 0.2 0.2 1" />
                                  <body name="middle_finger_2" pos="0 0 0.054">
                                    <inertial pos="0 0 0" quat="0.719796 0.528175 -0.157463 0.422055" mass="0.0355" diaginertia="2.20969e-05 2.20969e-05 2.20969e-05" />
                                    <joint name="middle_joint_2" pos="0 0 0" axis="0 1 0" limited="true" range="-0.274 1.809" />
                                    <geom size="0.0098 0.01375 0.0192" pos="0 0 0.0192" type="box" rgba="0.2 0.2 0.2 1" />
                                    <body name="middle_finger_3" pos="0 0 0.0384">
                                      <inertial pos="0 0 0" quat="0.760448 0.456478 -0.161222 0.432844" mass="0.0096" diaginertia="4.3506e-06 4.3506e-06 4.3506e-06" />
                                      <joint name="middle_joint_3" pos="0 0 0" axis="0 1 0" limited="true" range="-0.327 1.718" />
                                      <geom size="0.0098 0.01375 0.01335" pos="0 0 0.01335" type="box" rgba="0.2 0.2 0.2 1" />
                                      <body name="middle_tip" pos="0 0 0.0267">
                                        <inertial pos="0 0 0" mass="0.0168" diaginertia="9.68e-07 9.68e-07 9.68e-07" />
                                        <geom size="0.012" rgba="1 1 1 1" />
                                      </body>
                                    </body>
                                  </body>
                                </body>
                              </body>
                              <body name="ring_finger_0" pos="0 -0.0435 -0.001542" quat="0.999048 0.0436194 0 0">
                                <inertial pos="0 0 0" quat="0.707107 0.707107 0 0" mass="0.0119" diaginertia="1.01667e-06 1.01667e-06 6.47677e-07" />
                                <joint name="ring_joint_0" pos="0 0 0" axis="0 0 1" limited="true" range="-0.59 0.57" />
                                <geom size="0.0098 0.01375 0.0082" pos="0 0 0.0082" type="box" rgba="0.2 0.2 0.2 1" />
                                <body name="ring_finger_1" pos="0 0 0.0164">
                                  <inertial pos="0 0 0" quat="0.702596 0.559386 -0.178354 0.402039" mass="0.065" diaginertia="6.12799e-05 6.12799e-05 6.12799e-05" />
                                  <joint name="ring_joint_1" pos="0 0 0" axis="0 1 0" limited="true" range="-0.296 1.71" />
                                  <geom size="0.0098 0.01375 0.027" pos="0 0 0.027" type="box" rgba="0.2 0.2 0.2 1" />
                                  <body name="ring_finger_2" pos="0 0 0.054">
                                    <inertial pos="0 0 0" quat="0.719796 0.528175 -0.157463 0.422055" mass="0.0355" diaginertia="2.20969e-05 2.20969e-05 2.20969e-05" />
                                    <joint name="ring_joint_2" pos="0 0 0" axis="0 1 0" limited="true" range="-0.274 1.809" />
                                    <geom size="0.0098 0.01375 0.0192" pos="0 0 0.0192" type="box" rgba="0.2 0.2 0.2 1" />
                                    <body name="ring_finger_3" pos="0 0 0.0384">
                                      <inertial pos="0 0 0" quat="0.760448 0.456478 -0.161222 0.432844" mass="0.0096" diaginertia="4.3506e-06 4.3506e-06 4.3506e-06" />
                                      <joint name="ring_joint_3" pos="0 0 0" axis="0 1 0" limited="true" range="-0.327 1.718" />
                                      <geom size="0.0098 0.01375 0.01335" pos="0 0 0.01335" type="box" rgba="0.2 0.2 0.2 1" />
                                      <body name="ring_tip" pos="0 0 0.0267">
                                        <inertial pos="0 0 0" mass="0.0168" diaginertia="9.68e-07 9.68e-07 9.68e-07" />
                                        <geom size="0.012" rgba="1 1 1 1" />
                                      </body>
                                    </body>
                                  </body>
                                </body>
                              </body>
                              <body name="thumb_finger_0" pos="-0.0182 0.022333 -0.045987" quat="0.51279 -0.480013 -0.559612 -0.439851">
                                <inertial pos="0 0 0" quat="0.692635 0.569362 -0.07143 0.437013" mass="0.0176" diaginertia="1.73852e-05 1.73852e-05 1.73852e-05" />
                                <joint name="thumb_joint_0" pos="0 0 0" axis="-1 0 0" limited="true" range="0.363 1.62" />
                                <geom size="0.0179 0.017 0.02275" pos="-0.0179 0.009 0.0145" type="box" rgba="0.2 0.2 0.2 1" />
                                <body name="thumb_finger_1" pos="-0.027 0.005 0.0399">
                                  <inertial pos="0 0 0" quat="-0.0269589 0.880876 0.334036 0.334292" mass="0.0119" diaginertia="4.33621e-06 4.33621e-06 4.33621e-06" />
                                  <joint name="thumb_joint_1" pos="0 0 0" axis="0 0 1" limited="true" range="-0.205 1.263" />
                                  <geom size="0.0098 0.01375 0.00885" pos="0 0 0.00885" type="box" rgba="0.2 0.2 0.2 1" />
                                  <body name="thumb_finger_2" pos="0 0 0.0177">
                                    <inertial pos="0 0 0" quat="0.70472 0.55555 -0.174905 0.405146" mass="0.038" diaginertia="3.35111e-05 3.35111e-05 3.35111e-05" />
                                    <joint name="thumb_joint_2" pos="0 0 0" axis="0 1 0" limited="true" range="-0.289 1.744" />
                                    <geom size="0.0098 0.01375 0.0257" pos="0 0 0.0257" type="box" rgba="0.2 0.2 0.2 1" />
                                    <body name="thumb_finger_3" pos="0 0 0.0514">
                                      <inertial pos="0 0 0" quat="0.714142 0.538398 -0.162448 0.416821" mass="0.0388" diaginertia="2.68646e-05 2.68646e-05 2.68646e-05" />
                                      <joint name="thumb_joint_3" pos="0 0 0" axis="0 1 0" limited="true" range="-0.262 1.819" />
                                      <geom size="0.0098 0.01375 0.02115" pos="0 0 0.02115" type="box" rgba="0.2 0.2 0.2 1" />
                                      <body name="thumb_tip" pos="0 0 0.0423">
                                        <inertial pos="0 0 0" mass="0.0168" diaginertia="9.68e-07 9.68e-07 9.68e-07" />
                                        <geom size="0.012" rgba="1 1 1 1" />
                                      </body>
                                    </body>
                                  </body>
                                </body>
                              </body>
                            </body>
                          </body>
                        </body>
                      </body>
                    </body>
                  </body>
                </body>
              </body>
            </body>
          </body>
        </body>
      </body>
    </body>
  </worldbody>
</mujoco>
