<?xml version="1.0" ?>
<!-- =================================================================================== -->
<!-- |    This document was autogenerated by xacro from lbr4.robot.xacro               | -->
<!-- |    EDITING THIS FILE BY HAND IS NOT RECOMMENDED                                 | -->
<!-- =================================================================================== -->
<robot name="lbr4" xmlns:xacro="http://www.ros.org/wiki/xacro">
  <!-- ========================================================================================== -->
  <material name="Green">
    <color rgba="0.0 0.8 0.0 1.0"/>
  </material>
  <material name="DarkGrey">
    <color rgba="0.3 0.3 0.3 1.0"/>
  </material>
  <material name="Grey2">
    <color rgba="0.9 0.9 0.9 1.0"/>
  </material>
  <material name="Red">
    <color rgba="0.8 0.5 0.5 1.0"/>
  </material>
  <material name="Orange">
    <color rgba="1.0 0.423529411765 0.196078431373 1.0"/>
  </material>
  <selfCollide>true</selfCollide>
  <link name="base_link">
    <visual>
      <origin rpy="0 0 0" xyz="0 0 0"/>
      <geometry>
        <mesh filename="meshes/lbr4/base.stl"/>
      </geometry>
      <material name="Grey"/>
    </visual>
    <collision>
      <origin rpy="0 0 0" xyz="0 0 0"/>
      <geometry>
        <mesh filename="meshes/lbr4/base.stl"/>
      </geometry>
    </collision>
  </link>
  <gazebo reference="base_link">
    <material>Gazebo/Grey</material>
  </gazebo>
  <!-- joint between {parent} and arm_0_link -->
  <joint name="base_link_base" type="fixed">
    <origin rpy="0 0 0" xyz="0.0015 -0.0015 0.009"/>
    <parent link="base_link"/>
    <child link="lbr4_0_link"/>
  </joint>
  <link name="lbr4_0_link">
    <inertial>
      <origin rpy="0.503323678478 -0.189146421623 0.277526064738" xyz="0.0099787706820535227 -0.00048169854600738104 -0.25485509312792326"/>
      <mass value="1.5"/>
      <inertia ixx="0.00805112828804" ixy="0" ixz="0" iyy="0.00845152236845" iyz="0" izz="0.00863585824764"/>
    </inertial>
    <visual>
      <origin rpy="0 0 3.14159265359" xyz="0 0 0"/>
      <geometry>
        <mesh filename="meshes/lbr4/link0.stl"/>
      </geometry>
      <material name="Orange"/>
    </visual>
    <collision>
      <origin rpy="0 0 0" xyz="0 0 0.0515"/>
      <geometry>
        <cylinder length="0.103" radius="0.08"/>
      </geometry>
    </collision>
  </link>
  <!-- joint between arm_0_link and arm_1_link -->
  <joint name="lbr4_j0" type="revolute">
    <parent link="lbr4_0_link"/>
    <child link="lbr4_1_link"/>
    <origin rpy="0 0 0" xyz="0 0 0.103"/>
    <axis xyz="0 0 1"/>
    <dynamics damping="5"/>
    <limit effort="176" lower="-2.879" upper="2.879" velocity="1.91"/>
  </joint>
  <link name="lbr4_1_link">
    <inertial>
      <origin rpy="0.239538165056 0.00537995201801 0.0492155584082" xyz="2.1826998880744087e-05 -0.021623840412335664 -0.07915171924289198"/>
      <mass value="1.5"/>
      <inertia ixx="0.0129545076394" ixy="0" ixz="0" iyy="0.0128178432409" iyz="0" izz="0.00442072765916"/>
    </inertial>
    <visual>
      <origin rpy="0 0 3.14159265359" xyz="0 0 0"/>
      <geometry>
        <mesh filename="meshes/lbr4/link1.stl"/>
      </geometry>
      <material name="Orange"/>
    </visual>
    <collision>
      <origin rpy="0 0 0" xyz="0 0.017 0.135"/>
      <geometry>
        <box size="0.12 0.16 0.27"/>
      </geometry>
    </collision>
  </link>
  <!-- joint between arm_1_link and arm_2_link -->
  <joint name="lbr4_j1" type="revolute">
    <parent link="lbr4_1_link"/>
    <child link="lbr4_2_link"/>
    <dynamics damping="5"/>
    <origin rpy="0 0 0" xyz="0 -0.002 0.208"/>
    <axis xyz="0 -1 0"/>
    <limit effort="176" lower="-2.007" upper="2.007" velocity="1.91"/>
  </joint>
  <link name="lbr4_2_link">
    <inertial>
      <origin rpy="0.252444092172 -0.0167820344187 0.0575928285281" xyz="-0.0010097053542516513 0.028478464648332931 0.082033627936009448"/>
      <mass value="1.5"/>
      <inertia ixx="0.0132950018592" ixy="0" ixz="0" iyy="0.0131003199685" iyz="0" izz="0.0044657387969"/>
    </inertial>
    <visual>
      <origin rpy="0 0 3.14159265359" xyz="0 0 0"/>
      <geometry>
        <mesh filename="meshes/lbr4/link2.stl"/>
      </geometry>
      <material name="Orange"/>
    </visual>
    <collision>
      <origin rpy="0 0 0" xyz="0 -0.017 0.075"/>
      <geometry>
        <box size="0.12 0.16 0.27"/>
      </geometry>
    </collision>
  </link>
  <!-- joint between arm_2_link and arm_3_link -->
  <joint name="lbr4_j2" type="revolute">
    <parent link="lbr4_2_link"/>
    <child link="lbr4_3_link"/>
    <dynamics damping="5"/>
    <origin rpy="0 0 0" xyz="0 0 0.1915"/>
    <axis xyz="0 0 1"/>
    <limit effort="100" lower="-2.879" upper="2.879" velocity="2.234"/>
  </joint>
  <link name="lbr4_3_link">
    <inertial>
      <origin rpy="-0.211279484805 -0.0186487662306 -0.00721347462905" xyz="-0.00068512472584392442 0.022787627643261723 -0.078806475454300237"/>
      <mass value="1.5"/>
      <inertia ixx="0.0127763513867" ixy="0" ixz="0" iyy="0.0128011372133" iyz="0" izz="0.0043627376553"/>
    </inertial>
    <visual>
      <origin rpy="0 0 3.14159265359" xyz="0 0 0"/>
      <geometry>
        <mesh filename="meshes/lbr4/link3.stl"/>
      </geometry>
      <material name="Orange"/>
    </visual>
    <collision>
      <origin rpy="0 0 0" xyz="0 -0.017 0.135"/>
      <geometry>
        <box size="0.12 0.16 0.27"/>
      </geometry>
    </collision>
  </link>
  <!-- joint between arm_3_link and arm_4_link -->
  <joint name="lbr4_j3" type="revolute">
    <parent link="lbr4_3_link"/>
    <child link="lbr4_4_link"/>
    <dynamics damping="5"/>
    <origin rpy="0 0 0" xyz="0 0.002 0.2085"/>
    <axis xyz="0 1 0"/>
    <limit effort="100" lower="-2.007" upper="2.007" velocity="2.234"/>
  </joint>
  <link name="lbr4_4_link">
    <inertial>
      <origin rpy="0.259090664398 -0.00225330262131 0.0469419954367" xyz="-0.00025120620404353643 0.027040543208881447 0.082599870266635594"/>
      <mass value="1.5"/>
      <inertia ixx="0.0132276730313" ixy="0" ixz="0" iyy="0.0130734228464" iyz="0" izz="0.00439977729281"/>
    </inertial>
    <visual>
      <origin rpy="0 0 3.14159265359" xyz="0 0 0"/>
      <geometry>
        <mesh filename="meshes/lbr4/link4.stl"/>
      </geometry>
      <material name="Orange"/>
    </visual>
    <collision>
      <origin rpy="0 0 0" xyz="0 0.017 0.075"/>
      <geometry>
        <box size="0.12 0.16 0.27"/>
      </geometry>
    </collision>
  </link>
  <!-- joint between arm_4_link and arm_5_link -->
  <joint name="lbr4_j4" type="revolute">
    <parent link="lbr4_4_link"/>
    <child link="lbr4_5_link"/>
    <dynamics damping="5"/>
    <origin rpy="0 0 0" xyz="0 0 0.1915"/>
    <axis xyz="0 0 1"/>
    <limit effort="100" lower="-2.879" upper="2.879" velocity="3.56"/>
  </joint>
  <link name="lbr4_5_link">
    <inertial>
      <origin rpy="-0.399346437469 -0.0238815557936 0.011018430381" xyz="-7.2951660343995983e-05 0.034300558520003806 -0.082836449419419589"/>
      <mass value="1.5"/>
      <inertia ixx="0.0124407882151" ixy="0" ixz="0" iyy="0.0124710412724" iyz="0" izz="0.00438005667842"/>
    </inertial>
    <visual>
      <origin rpy="0 0 3.14159265359" xyz="0 0 0"/>
      <geometry>
        <mesh filename="meshes/lbr4/link5.stl"/>
      </geometry>
      <material name="Orange"/>
    </visual>
    <collision>
      <origin rpy="0 0 0" xyz="0 0.017 0.13"/>
      <geometry>
        <box size="0.12 0.16 0.27"/>
      </geometry>
    </collision>
  </link>
  <!-- joint between arm_5_link and arm_6_link -->
  <joint name="lbr4_j5" type="revolute">
    <parent link="lbr4_5_link"/>
    <child link="lbr4_6_link"/>
    <dynamics damping="5"/>
    <origin rpy="0 0 0" xyz="0 0 0.199"/>
    <axis xyz="0 -1 0"/>
    <limit effort="38" lower="-2.007" upper="2.007" velocity="3.211"/>
  </joint>
  <link name="lbr4_6_link">
    <inertial>
      <origin rpy="0.0273247151986 -0.416007068876 -0.06463859276" xyz="0.0033265785100209406 -0.00025060639771109469 0.0006250581115164501"/>
      <mass value="0.75"/>
      <inertia ixx="0.00284169077177" ixy="0" ixz="0" iyy="0.00298256896714" iyz="0" izz="0.00296892557443"/>
    </inertial>
    <visual>
      <origin rpy="0 0 3.14159265359" xyz="0 0 0"/>
      <geometry>
        <mesh filename="meshes/lbr4/link6.stl"/>
      </geometry>
      <material name="DarkGrey"/>
    </visual>
    <collision>
      <origin rpy="0 0 0" xyz="0 0 0"/>
      <geometry>
        <sphere radius="0.078"/>
      </geometry>
    </collision>
  </link>
  <!-- joint between arm_6_link and arm_7_link -->
  <joint name="lbr4_j6" type="revolute">
    <parent link="lbr4_6_link"/>
    <child link="lbr4_7_link"/>
    <dynamics damping="5"/>
    <origin rpy="0 0 0" xyz="0 0 0.078"/>
    <axis xyz="0 0 1"/>
    <limit effort="38" lower="-2.879" upper="2.879" velocity="3.21"/>
  </joint>
  <link name="lbr4_7_link">
    <inertial>
      <origin rpy="-0.00140457256351 -0.0113238487485 -0.621939623896" xyz="-1.0508863000830793e-05 0.00049391465901896074 0.062507829615577853"/>
      <mass value="0.075"/>
      <inertia ixx="5.81502716972e-05" ixy="0" ixz="0" iyy="5.84472283068e-05" iyz="0" izz="9.68983240391e-05"/>
    </inertial>
    <visual>
      <origin rpy="0 0 3.14159265359" xyz="0 0 0"/>
      <geometry>
        <mesh filename="meshes/lbr4/link7.stl"/>
      </geometry>
      <material name="Grey"/>
    </visual>
    <collision>
      <origin rpy="0 0 0" xyz="0 0 0"/>
      <geometry>
        <box size="0.05 0.05 0.01"/>
      </geometry>
    </collision>
  </link>
  <!-- World -->
  <link name="world"/>
  <!-- ROS control plugin -->
  <gazebo>
    <plugin filename="libgazebo_ros_control.so" name="gazebo_ros_control"/>
  </gazebo>
  <!-- disable fixed linking to allow referencing joint 0 -->
  <gazebo reference="world_to_table_joint">
    <disableFixedJointLumping>true</disableFixedJointLumping>
  </gazebo>
  <gazebo reference="table_to_base_joint">
    <disableFixedJointLumping>true</disableFixedJointLumping>
  </gazebo>
  <!--
  <gazebo reference="base_link_base">
    <disableFixedJointLumping>true</disableFixedJointLumping>
  </gazebo>
  -->
  <gazebo reference="lbr4_mount_joint">
    <disableFixedJointLumping>true</disableFixedJointLumping>
  </gazebo>
  <gazebo reference="lbr4_j0">
    <disableFixedJointLumping>true</disableFixedJointLumping>
  </gazebo>
  <!-- Gazebo materials -->
  <gazebo reference="lbr4_0_link">
    <material>Gazebo/Orange</material>
  </gazebo>
  <gazebo reference="lbr4_1_link">
    <material>Gazebo/Orange</material>
  </gazebo>
  <gazebo reference="lbr4_2_link">
    <material>Gazebo/Orange</material>
  </gazebo>
  <gazebo reference="lbr4_3_link">
    <material>Gazebo/Orange</material>
  </gazebo>
  <gazebo reference="lbr4_4_link">
    <material>Gazebo/Orange</material>
  </gazebo>
  <gazebo reference="lbr4_5_link">
    <material>Gazebo/Orange</material>
  </gazebo>
  <gazebo reference="lbr4_6_link">
    <material>Gazebo/Grey</material>
  </gazebo>
  <gazebo reference="lbr4_7_link">
    <material>Gazebo/Black</material>
  </gazebo>
  <transmission name="lbr4_trans0">
    <type>transmission_interface/SimpleTransmission</type>
    <joint name="lbr4_j0">
      <hardwareInterface>EffortJointInterface</hardwareInterface>
    </joint>
    <actuator name="lbr4_motor0">
      <hardwareInterface>EffortJointInterface</hardwareInterface>
      <mechanicalReduction>1</mechanicalReduction>
    </actuator>
  </transmission>
  <transmission name="lbr4_trans1">
    <type>transmission_interface/SimpleTransmission</type>
    <joint name="lbr4_j1">
      <hardwareInterface>EffortJointInterface</hardwareInterface>
    </joint>
    <actuator name="lbr4_motor1">
      <hardwareInterface>EffortJointInterface</hardwareInterface>
      <mechanicalReduction>1</mechanicalReduction>
    </actuator>
  </transmission>
  <transmission name="lbr4_trans2">
    <type>transmission_interface/SimpleTransmission</type>
    <joint name="lbr4_j2">
      <hardwareInterface>EffortJointInterface</hardwareInterface>
    </joint>
    <actuator name="lbr4_motor2">
      <hardwareInterface>EffortJointInterface</hardwareInterface>
      <mechanicalReduction>1</mechanicalReduction>
    </actuator>
  </transmission>
  <transmission name="lbr4_trans3">
    <type>transmission_interface/SimpleTransmission</type>
    <joint name="lbr4_j3">
      <hardwareInterface>EffortJointInterface</hardwareInterface>
    </joint>
    <actuator name="lbr4_motor3">
      <hardwareInterface>EffortJointInterface</hardwareInterface>
      <mechanicalReduction>1</mechanicalReduction>
    </actuator>
  </transmission>
  <transmission name="lbr4_trans4">
    <type>transmission_interface/SimpleTransmission</type>
    <joint name="lbr4_j4">
      <hardwareInterface>EffortJointInterface</hardwareInterface>
    </joint>
    <actuator name="lbr4_motor4">
      <hardwareInterface>EffortJointInterface</hardwareInterface>
      <mechanicalReduction>1</mechanicalReduction>
    </actuator>
  </transmission>
  <transmission name="lbr4_trans5">
    <type>transmission_interface/SimpleTransmission</type>
    <joint name="lbr4_j5">
      <hardwareInterface>EffortJointInterface</hardwareInterface>
    </joint>
    <actuator name="lbr4_motor5">
      <hardwareInterface>EffortJointInterface</hardwareInterface>
      <mechanicalReduction>1</mechanicalReduction>
    </actuator>
  </transmission>
  <transmission name="lbr4_trans6">
    <type>transmission_interface/SimpleTransmission</type>
    <joint name="lbr4_j6">
      <hardwareInterface>EffortJointInterface</hardwareInterface>
    </joint>
    <actuator name="lbr4_motor6">
      <hardwareInterface>EffortJointInterface</hardwareInterface>
      <mechanicalReduction>1</mechanicalReduction>
    </actuator>
  </transmission>
  <!-- ======================================= Masses ======================================== -->
  <!-- These are rough approximations, the total hand mass was measured to be about 0.9kg,     -->
  <!-- most of it concentrated in the shell anyways, so for sake of arm controller, most mass  -->
  <!-- is being given to shell/pad, treating fingers as almost massless, so that KDL chain for -->
  <!-- arm can just go through the palm pad and be accounting for most of the hand mass.       -->
  <!-- ====================================== Link Macros ==================================== -->
  <!-- ===================================== Joint Macros ===================================== -->
  <!-- =============================== Kinematic Chain =============================== -->
  <link name="lower_shell">
    <visual>
      <origin rpy="0 0 0" xyz="0 0 0"/>
      <geometry>
        <mesh filename="meshes/reflex/base_link.STL"/>
      </geometry>
      <material name="black"/>
    </visual>
    <inertial>
      <origin rpy="0 0 0" xyz="0 0 0"/>
      <mass value="0.8"/>
      <inertia ixx="0.00178513333333" ixy="0.0" ixz="0.0" iyy="0.00152346666667" iyz="0.0" izz="0.000842466666667"/>
    </inertial>
    <collision>
      <origin rpy="0 0 0" xyz="0 0 0"/>
      <geometry>
        <mesh filename="meshes/reflex/base_link.STL"/>
      </geometry>
    </collision>
  </link>
  <link name="pad">
    <visual>
      <origin rpy="0 0 0" xyz="0 0 0"/>
      <geometry>
        <mesh filename="meshes/reflex/pad.STL"/>
      </geometry>
      <material name="dark_grey">
        <color rgba="0.2 0.2 0.2 1"/>
      </material>
    </visual>
    <inertial>
      <origin rpy="0 0 0" xyz="0 0 0"/>
      <mass value="0.1"/>
      <inertia ixx="0.000223141666667" ixy="0.0" ixz="0.0" iyy="0.000190433333333" iyz="0.0" izz="0.000105308333333"/>
    </inertial>
    <collision>
      <origin rpy="0 0 0" xyz="0 0 0"/>
      <geometry>
        <mesh filename="meshes/reflex/pad.STL"/>
      </geometry>
    </collision>
  </link>
  <link name="swivel_1">
    <visual>
      <origin rpy="0 0 0" xyz="0 0 0"/>
      <geometry>
        <mesh filename="meshes/reflex/swivel_1.STL"/>
      </geometry>
      <material name="black"/>
    </visual>
    <inertial>
      <origin rpy="0 0 0" xyz="0 0 0"/>
      <mass value="0.0001"/>
      <inertia ixx="1.60333333333e-08" ixy="0.0" ixz="0.0" iyy="1.15333333333e-08" iyz="0.0" izz="1.25666666667e-08"/>
    </inertial>
    <collision>
      <origin rpy="0 0 0" xyz="0 0 0"/>
      <geometry>
        <mesh filename="meshes/reflex/swivel_1.STL"/>
      </geometry>
    </collision>
  </link>
  <link name="proximal_1">
    <visual>
      <origin rpy="3.1459 0 0" xyz="-0.011 0.007 0.011"/>
      <geometry>
        <mesh filename="meshes/reflex/proximal.STL"/>
      </geometry>
      <material name="black"/>
    </visual>
    <inertial>
      <origin rpy="3.1459 0 0" xyz="-0.011 0.007 0.011"/>
      <mass value="0.0001"/>
      <inertia ixx="2.29508333333e-07" ixy="0.0" ixz="0.0" iyy="4.53416666667e-08" iyz="0.0" izz="1.90833333333e-07"/>
    </inertial>
    <collision>
      <origin rpy="3.1459 0 0" xyz="-0.011 0.007 0.011"/>
      <geometry>
        <mesh filename="meshes/reflex/proximal.STL"/>
      </geometry>
    </collision>
  </link>
  <link name="proximal_pad_1">
    <visual>
      <origin rpy="1.5708 1.5708 0" xyz="-0.008 0.014 -0.002"/>
      <geometry>
        <mesh filename="meshes/reflex/proximal_pad.STL"/>
      </geometry>
      <material name="dark_grey">
        <color rgba="0.2 0.2 0.2 1"/>
      </material>
    </visual>
    <inertial>
      <origin rpy="1.5708 1.5708 0" xyz="-0.008 0.014 -0.002"/>
      <mass value="0.0001"/>
      <inertia ixx="2.29508333333e-07" ixy="0.0" ixz="0.0" iyy="4.22166666667e-08" iyz="0.0" izz="1.87708333333e-07"/>
    </inertial>
    <collision>
      <origin rpy="1.5708 1.5708 0" xyz="-0.008 0.014 -0.002"/>
      <geometry>
        <mesh filename="meshes/reflex/proximal_pad.STL"/>
      </geometry>
    </collision>
  </link>
  <link name="finger_1_flex_link">
    <visual>
      <origin rpy="0 0 0" xyz="0.0005 0 -0.003"/>
      <geometry>
        <box size="0.017 0.014 0.0065"/>
      </geometry>
      <material name="gold">
        <color rgba="0.996078431373 0.847058823529 0.364705882353 1"/>
      </material>
    </visual>
    <inertial>
      <origin rpy="0 0 0" xyz="0 0 0"/>
      <mass value="0.0001"/>
      <inertia ixx="3.50833333333e-09" ixy="0.0" ixz="0.0" iyy="2.08333333333e-09" iyz="0.0" izz="1.84166666667e-09"/>
    </inertial>
    <collision>
      <origin rpy="0 0 0" xyz="0 0 0"/>
      <geometry>
        <box size="0.01 0.01 0.01"/>
      </geometry>
    </collision>
  </link>
  <link name="distal_1">
    <visual>
      <origin rpy="3.1459 0 0" xyz="-0.077 0.007 0.007"/>
      <geometry>
        <mesh filename="meshes/reflex/distal.STL"/>
      </geometry>
      <material name="black"/>
    </visual>
    <inertial>
      <origin rpy="3.1459 0 0" xyz="-0.077 0.007 0.007"/>
      <mass value="0.0001"/>
      <inertia ixx="2.00175e-07" ixy="0.0" ixz="0.0" iyy="1.50833333333e-08" iyz="0.0" izz="1.89908333333e-07"/>
    </inertial>
    <collision>
      <origin rpy="3.1459 0 0" xyz="-0.077 0.007 0.007"/>
      <geometry>
        <mesh filename="meshes/reflex/distal.STL"/>
      </geometry>
    </collision>
  </link>
  <link name="distal_pad_1">
    <visual>
      <origin rpy="1.5708 1.5708 0" xyz="-0.00825 0.009 0.057"/>
      <geometry>
        <mesh filename="meshes/reflex/distal_pad.STL"/>
      </geometry>
      <material name="dark_grey">
        <color rgba="0.2 0.2 0.2 1"/>
      </material>
    </visual>
    <inertial>
      <origin rpy="1.5708 1.5708 0" xyz="-0.00825 0.009 0.057"/>
      <mass value="0.0001"/>
      <inertia ixx="2.00175e-07" ixy="0.0" ixz="0.0" iyy="1.28833333333e-08" iyz="0.0" izz="1.87708333333e-07"/>
    </inertial>
    <collision>
      <origin rpy="1.5708 1.5708 0" xyz="-0.00825 0.009 0.057"/>
      <geometry>
        <mesh filename="meshes/reflex/distal_pad.STL"/>
      </geometry>
    </collision>
  </link>
  <link name="swivel_2">
    <visual>
      <origin rpy="0 0 0" xyz="0 0 0"/>
      <geometry>
        <mesh filename="meshes/reflex/swivel_2.STL"/>
      </geometry>
      <material name="black"/>
    </visual>
    <inertial>
      <origin rpy="0 0 0" xyz="0 0 0"/>
      <mass value="0.0001"/>
      <inertia ixx="1.60333333333e-08" ixy="0.0" ixz="0.0" iyy="1.15333333333e-08" iyz="0.0" izz="1.25666666667e-08"/>
    </inertial>
    <collision>
      <origin rpy="0 0 0" xyz="0 0 0"/>
      <geometry>
        <mesh filename="meshes/reflex/swivel_2.STL"/>
      </geometry>
    </collision>
  </link>
  <link name="proximal_2">
    <visual>
      <origin rpy="3.1459 0 0" xyz="-0.011 0.007 0.011"/>
      <geometry>
        <mesh filename="meshes/reflex/proximal.STL"/>
      </geometry>
      <material name="black"/>
    </visual>
    <inertial>
      <origin rpy="3.1459 0 0" xyz="-0.011 0.007 0.011"/>
      <mass value="0.0001"/>
      <inertia ixx="2.29508333333e-07" ixy="0.0" ixz="0.0" iyy="4.53416666667e-08" iyz="0.0" izz="1.90833333333e-07"/>
    </inertial>
    <collision>
      <origin rpy="3.1459 0 0" xyz="-0.011 0.007 0.011"/>
      <geometry>
        <mesh filename="meshes/reflex/proximal.STL"/>
      </geometry>
    </collision>
  </link>
  <link name="proximal_pad_2">
    <visual>
      <origin rpy="1.5708 1.5708 0" xyz="-0.008 0.014 -0.002"/>
      <geometry>
        <mesh filename="meshes/reflex/proximal_pad.STL"/>
      </geometry>
      <material name="dark_grey">
        <color rgba="0.2 0.2 0.2 1"/>
      </material>
    </visual>
    <inertial>
      <origin rpy="1.5708 1.5708 0" xyz="-0.008 0.014 -0.002"/>
      <mass value="0.0001"/>
      <inertia ixx="2.29508333333e-07" ixy="0.0" ixz="0.0" iyy="4.22166666667e-08" iyz="0.0" izz="1.87708333333e-07"/>
    </inertial>
    <collision>
      <origin rpy="1.5708 1.5708 0" xyz="-0.008 0.014 -0.002"/>
      <geometry>
        <mesh filename="meshes/reflex/proximal_pad.STL"/>
      </geometry>
    </collision>
  </link>
  <link name="finger_2_flex_link">
    <visual>
      <origin rpy="0 0 0" xyz="0.0005 0 -0.003"/>
      <geometry>
        <box size="0.017 0.014 0.0065"/>
      </geometry>
      <material name="gold">
        <color rgba="0.996078431373 0.847058823529 0.364705882353 1"/>
      </material>
    </visual>
    <inertial>
      <origin rpy="0 0 0" xyz="0 0 0"/>
      <mass value="0.0001"/>
      <inertia ixx="3.50833333333e-09" ixy="0.0" ixz="0.0" iyy="2.08333333333e-09" iyz="0.0" izz="1.84166666667e-09"/>
    </inertial>
    <collision>
      <origin rpy="0 0 0" xyz="0 0 0"/>
      <geometry>
        <box size="0.01 0.01 0.01"/>
      </geometry>
    </collision>
  </link>
  <link name="distal_2">
    <visual>
      <origin rpy="3.1459 0 0" xyz="-0.077 0.007 0.007"/>
      <geometry>
        <mesh filename="meshes/reflex/distal.STL"/>
      </geometry>
      <material name="black"/>
    </visual>
    <inertial>
      <origin rpy="3.1459 0 0" xyz="-0.077 0.007 0.007"/>
      <mass value="0.0001"/>
      <inertia ixx="2.00175e-07" ixy="0.0" ixz="0.0" iyy="1.50833333333e-08" iyz="0.0" izz="1.89908333333e-07"/>
    </inertial>
    <collision>
      <origin rpy="3.1459 0 0" xyz="-0.077 0.007 0.007"/>
      <geometry>
        <mesh filename="meshes/reflex/distal.STL"/>
      </geometry>
    </collision>
  </link>
  <link name="distal_pad_2">
    <visual>
      <origin rpy="1.5708 1.5708 0" xyz="-0.00825 0.009 0.057"/>
      <geometry>
        <mesh filename="meshes/reflex/distal_pad.STL"/>
      </geometry>
      <material name="dark_grey">
        <color rgba="0.2 0.2 0.2 1"/>
      </material>
    </visual>
    <inertial>
      <origin rpy="1.5708 1.5708 0" xyz="-0.00825 0.009 0.057"/>
      <mass value="0.0001"/>
      <inertia ixx="2.00175e-07" ixy="0.0" ixz="0.0" iyy="1.28833333333e-08" iyz="0.0" izz="1.87708333333e-07"/>
    </inertial>
    <collision>
      <origin rpy="1.5708 1.5708 0" xyz="-0.00825 0.009 0.057"/>
      <geometry>
        <mesh filename="meshes/reflex/distal_pad.STL"/>
      </geometry>
    </collision>
  </link>
  <link name="proximal_3">
    <visual>
      <origin rpy="3.1459 0 0" xyz="-0.011 0.007 0.011"/>
      <geometry>
        <mesh filename="meshes/reflex/proximal.STL"/>
      </geometry>
      <material name="black"/>
    </visual>
    <inertial>
      <origin rpy="3.1459 0 0" xyz="-0.011 0.007 0.011"/>
      <mass value="0.0001"/>
      <inertia ixx="2.29508333333e-07" ixy="0.0" ixz="0.0" iyy="4.53416666667e-08" iyz="0.0" izz="1.90833333333e-07"/>
    </inertial>
    <collision>
      <origin rpy="3.1459 0 0" xyz="-0.011 0.007 0.011"/>
      <geometry>
        <mesh filename="meshes/reflex/proximal.STL"/>
      </geometry>
    </collision>
  </link>
  <link name="proximal_pad_3">
    <visual>
      <origin rpy="1.5708 1.5708 0" xyz="-0.008 0.014 -0.002"/>
      <geometry>
        <mesh filename="meshes/reflex/proximal_pad.STL"/>
      </geometry>
      <material name="dark_grey">
        <color rgba="0.2 0.2 0.2 1"/>
      </material>
    </visual>
    <inertial>
      <origin rpy="1.5708 1.5708 0" xyz="-0.008 0.014 -0.002"/>
      <mass value="0.0001"/>
      <inertia ixx="2.29508333333e-07" ixy="0.0" ixz="0.0" iyy="4.22166666667e-08" iyz="0.0" izz="1.87708333333e-07"/>
    </inertial>
    <collision>
      <origin rpy="1.5708 1.5708 0" xyz="-0.008 0.014 -0.002"/>
      <geometry>
        <mesh filename="meshes/reflex/proximal_pad.STL"/>
      </geometry>
    </collision>
  </link>
  <link name="finger_3_flex_link">
    <visual>
      <origin rpy="0 0 0" xyz="0.0005 0 -0.003"/>
      <geometry>
        <box size="0.017 0.014 0.0065"/>
      </geometry>
      <material name="gold">
        <color rgba="0.996078431373 0.847058823529 0.364705882353 1"/>
      </material>
    </visual>
    <inertial>
      <origin rpy="0 0 0" xyz="0 0 0"/>
      <mass value="0.0001"/>
      <inertia ixx="3.50833333333e-09" ixy="0.0" ixz="0.0" iyy="2.08333333333e-09" iyz="0.0" izz="1.84166666667e-09"/>
    </inertial>
    <collision>
      <origin rpy="0 0 0" xyz="0 0 0"/>
      <geometry>
        <box size="0.01 0.01 0.01"/>
      </geometry>
    </collision>
  </link>
  <link name="distal_3">
    <visual>
      <origin rpy="3.1459 0 0" xyz="-0.077 0.007 0.007"/>
      <geometry>
        <mesh filename="meshes/reflex/distal.STL"/>
      </geometry>
      <material name="black"/>
    </visual>
    <inertial>
      <origin rpy="3.1459 0 0" xyz="-0.077 0.007 0.007"/>
      <mass value="0.0001"/>
      <inertia ixx="2.00175e-07" ixy="0.0" ixz="0.0" iyy="1.50833333333e-08" iyz="0.0" izz="1.89908333333e-07"/>
    </inertial>
    <collision>
      <origin rpy="3.1459 0 0" xyz="-0.077 0.007 0.007"/>
      <geometry>
        <mesh filename="meshes/reflex/distal.STL"/>
      </geometry>
    </collision>
  </link>
  <link name="distal_pad_3">
    <visual>
      <origin rpy="1.5708 1.5708 0" xyz="-0.00825 0.009 0.057"/>
      <geometry>
        <mesh filename="meshes/reflex/distal_pad.STL"/>
      </geometry>
      <material name="dark_grey">
        <color rgba="0.2 0.2 0.2 1"/>
      </material>
    </visual>
    <inertial>
      <origin rpy="1.5708 1.5708 0" xyz="-0.00825 0.009 0.057"/>
      <mass value="0.0001"/>
      <inertia ixx="2.00175e-07" ixy="0.0" ixz="0.0" iyy="1.28833333333e-08" iyz="0.0" izz="1.87708333333e-07"/>
    </inertial>
    <collision>
      <origin rpy="1.5708 1.5708 0" xyz="-0.00825 0.009 0.057"/>
      <geometry>
        <mesh filename="meshes/reflex/distal_pad.STL"/>
      </geometry>
    </collision>
  </link>
  <joint name="prox1_pad_joint" type="fixed">
    <origin rpy="1.5707963267949 0 -1.5707963267949" xyz="0 0 0"/>
    <parent link="proximal_1"/>
    <child link="proximal_pad_1"/>
    <axis xyz="0 0 0"/>
  </joint>
  <joint name="dist1_pad_joint" type="fixed">
    <origin rpy="1.5707963267949 0 -1.5707963267949" xyz="-0.01 0 0.001"/>
    <parent link="distal_1"/>
    <child link="distal_pad_1"/>
    <axis xyz="0 0 0"/>
  </joint>
  <joint name="prox2_pad_joint" type="fixed">
    <origin rpy="1.5707963267949 0 -1.5707963267949" xyz="0 0 0"/>
    <parent link="proximal_2"/>
    <child link="proximal_pad_2"/>
    <axis xyz="0 0 0"/>
  </joint>
  <joint name="dist2_pad_joint" type="fixed">
    <origin rpy="1.5707963267949 0 -1.5707963267949" xyz="-0.01 0 0.001"/>
    <parent link="distal_2"/>
    <child link="distal_pad_2"/>
    <axis xyz="0 0 0"/>
  </joint>
  <joint name="prox3_pad_joint" type="fixed">
    <origin rpy="1.5707963267949 0 -1.5707963267949" xyz="0 0 0"/>
    <parent link="proximal_3"/>
    <child link="proximal_pad_3"/>
    <axis xyz="0 0 0"/>
  </joint>
  <joint name="dist3_pad_joint" type="fixed">
    <origin rpy="1.5707963267949 0 -1.5707963267949" xyz="-0.01 0 0.001"/>
    <parent link="distal_3"/>
    <child link="distal_pad_3"/>
    <axis xyz="0 0 0"/>
  </joint>
  <joint name="pad_joint" type="fixed">
    <origin rpy="1.5707963267949 5.55111512312578E-17 -1.5707963267949" xyz="0.02 0 0.063"/>
    <parent link="lower_shell"/>
    <child link="pad"/>
    <axis xyz="0 0 0"/>
  </joint>
  <!-- <joint name="preshape_1" type="revolute"> -->
  <joint name="preshape_1" type="fixed">
    <origin rpy="6.75550818663469E-16 1.97993848419069E-16 -2.77555756156289E-16" xyz="0.0503973683071414 -0.026 0.063"/>
    <parent link="lower_shell"/>
    <child link="swivel_1"/>
    <axis xyz="0 0 -1"/>
    <limit effort="50000" lower="0.0" upper="1.5707963268" velocity="10000"/>
  </joint>
  <!-- <joint name="proximal_joint_1" type="revolute"> -->
  <joint name="proximal_joint_1" type="fixed">
    <origin rpy="-6.20039667432211E-16 0.28 2.22044604925031E-16" xyz="0.01 0 0.0186"/>
    <parent link="swivel_1"/>
    <child link="proximal_1"/>
    <axis xyz="0 -1 0"/>
    <limit effort="50000" lower="0.0" upper="3.14159265359" velocity="10000"/>
  </joint>
  <joint name="proximal_to_flex_1" type="fixed">
    <origin rpy="0 0 0" xyz="0.07 0 0.004"/>
    <parent link="proximal_1"/>
    <child link="finger_1_flex_link"/>
    <axis xyz="0 0 0"/>
  </joint>
  <joint name="flex_1_to_distal" type="fixed">
    <origin rpy="0 0 0" xyz="0 0 0"/>
    <parent link="finger_1_flex_link"/>
    <child link="distal_1"/>
    <axis xyz="0 0 0"/>
  </joint>
  <joint name="proximal_to_flex_2" type="fixed">
    <origin rpy="0 0 0" xyz="0.07 0 0.004"/>
    <parent link="proximal_2"/>
    <child link="finger_2_flex_link"/>
    <axis xyz="0 0 0"/>
  </joint>
  <joint name="flex_2_to_distal" type="fixed">
    <origin rpy="0 0 0" xyz="0 0 0"/>
    <parent link="finger_2_flex_link"/>
    <child link="distal_2"/>
    <axis xyz="0 0 0"/>
  </joint>
  <joint name="proximal_to_flex_3" type="fixed">
    <origin rpy="0 0 0" xyz="0.07 0 0.004"/>
    <parent link="proximal_3"/>
    <child link="finger_3_flex_link"/>
    <axis xyz="0 0 0"/>
  </joint>
  <joint name="flex_3_to_distal" type="fixed">
    <origin rpy="0 0 0" xyz="0 0 0"/>
    <parent link="finger_3_flex_link"/>
    <child link="distal_3"/>
    <axis xyz="0 0 0"/>
  </joint>
  <!-- <joint name="preshape_2" type="revolute"> -->
  <joint name="preshape_2" type="fixed">
    <origin rpy="1.22459340959228E-15 -7.33448407631817E-16 -1.66533453693773E-16" xyz="0.0503973683071413 0.0259999999999999 0.063"/>
    <parent link="lower_shell"/>
    <child link="swivel_2"/>
    <axis xyz="0 0 -1"/>
    <limit effort="50000" lower="0.0" upper="1.5707963268" velocity="10000"/>
  </joint>
  <!-- <joint name="proximal_joint_2" type="revolute"> -->
  <joint name="proximal_joint_2" type="fixed">
    <origin rpy="-1.16908225836102E-15 0.28 1.11022302462515E-16" xyz="0.01 0 0.0186"/>
    <parent link="swivel_2"/>
    <child link="proximal_2"/>
    <axis xyz="0 -1 0"/>
    <limit effort="50000" lower="0.0" upper="3.14159265359" velocity="10000"/>
  </joint>
  <!-- <joint name="proximal_joint_3" type="revolute"> -->
  <joint name="proximal_joint_3" type="fixed">
    <origin rpy="-5.55111512312578E-17 0.28 3.14159265358979" xyz="-0.0299999999999996 0 0.0816000000000002"/>
    <parent link="lower_shell"/>
    <child link="proximal_3"/>
    <axis xyz="0 -1 0"/>
    <limit effort="50000" lower="0.0" upper="3.14159265359" velocity="10000"/>
  </joint>
  <!-- Leaving out tactile links/joints as they will not be visualized in Gazebo. They can be -->
  <!-- added back in if they will actually be used for sensing in simulation.  -->
  <!--
  <joint name="base_tactile_joint" type="fixed">
    <origin xyz="0 0 0" rpy="0 0 0" />
    <parent link="base_link" />
    <child link="base_tactile" />
  </joint>

  <link name="base_tactile"/>

  <link name="proximal_1_tactile" />

  <joint name="proximal_1_tactile_joint" type="fixed">
    <origin xyz="0 0 0" rpy="0 0 0" />
    <parent link="proximal_1" />
    <child link="proximal_1_tactile" />
  </joint>

  <joint name="proximal_2_tactile_joint" type="fixed">
    <origin xyz="0 0 0" rpy="0 0 0" />
    <parent link="proximal_2" />
    <child link="proximal_2_tactile" />
  </joint>

  <link name="proximal_2_tactile"/>

  <joint name="proximal_3_tactile_joint" type="fixed">
    <origin xyz="0 0 0" rpy="0 0 0" />
    <parent link="proximal_3" />
    <child link="proximal_3_tactile" />
  </joint>

  <link name="proximal_3_tactile"/>

  <joint name="distal_1_tactile_joint" type="fixed">
    <origin xyz="0 0 0" rpy="0 0 0" />
    <parent link="distal_1" />
    <child link="distal_1_tactile" />
  </joint>

  <link name="distal_1_tactile"/>

  <joint name="distal_2_tactile_joint" type="fixed">
    <origin xyz="0 0 0" rpy="0 0 0" />
    <parent link="distal_2" />
    <child link="distal_2_tactile" />
  </joint>

  <link name="distal_2_tactile"/>

  <joint name="distal_3_tactile_joint" type="fixed">
    <origin xyz="0 0 0" rpy="0 0 0" />
    <parent link="distal_3" />
    <child link="distal_3_tactile" />
  </joint>

  <link name="distal_3_tactile"/>
  -->
  <gazebo reference="lbr4_mount">
    <material>Gazebo/Grey</material>
  </gazebo>
  <link name="lbr4_mount">
    <inertial>
      <origin rpy="0 0 0" xyz="0 0 0"/>
      <mass value="0.199"/>
      <inertia ixx="0.000104475" ixy="0.0" ixz="0.0" iyy="0.000104475" iyz="0.0" izz="0.0002014875"/>
    </inertial>
    <visual>
      <origin rpy="0 0 0" xyz="0 0 0"/>
      <geometry>
        <mesh filename="meshes/mounts/kuka_mount.stl"/>
      </geometry>
      <material name="Grey"/>
    </visual>
    <collision>
      <origin rpy="0 0 0" xyz="0 0 0"/>
      <geometry>
        <mesh filename="meshes/mounts/kuka_mount.stl"/>
      </geometry>
    </collision>
  </link>
  <joint name="lb4_mount_joint" type="fixed">
    <origin rpy="-3.14159265359 0 0" xyz="0.0009 0.0009 0.015"/>
    <parent link="lbr4_7_link"/>
    <child link="lbr4_mount"/>
  </joint>
  <link name="reflex_mount">
    <inertial>
      <origin rpy="0 0 0" xyz="0 0 0"/>
      <mass value="0.18"/>
      <inertia ixx="7.818e-05" ixy="0.0" ixz="0.0" iyy="7.818e-05" iyz="0.0" izz="0.00015129"/>
    </inertial>
    <visual>
      <origin rpy="0 0 0" xyz="0 0 0"/>
      <geometry>
        <mesh filename="meshes/mounts/reflex_mount.STL"/>
      </geometry>
      <material name="Grey"/>
    </visual>
    <collision>
      <origin rpy="0 0 0" xyz="0 0 0"/>
      <geometry>
        <mesh filename="meshes/mounts/reflex_mount.STL"/>
      </geometry>
    </collision>
  </link>
  <gazebo reference="reflex_mount">
    <material>Gazebo/Grey</material>
  </gazebo>
  <joint name="reflex_mount_to_lbr4_mount" type="fixed">
    <parent link="lbr4_mount"/>
    <child link="reflex_mount"/>
    <origin rpy="0 1.57079632679 0" xyz="-0.003 -0.002 0"/>
  </joint>
  <joint name="reflex_mount_to_reflex" type="fixed">
    <parent link="reflex_mount"/>
    <child link="lower_shell"/>
    <origin rpy="3.14159265359 -1.57079632679 0" xyz="0.013 0.0025 0"/>
  </joint>
  <!-- Transmissions -->
  <!-- <xacro:include filename="$(find ll4ma_robots_description)/urdf/reflex/reflex.transmission.xacro"/> -->
  <!-- Materials -->
  <gazebo reference="lower_shell">
    <material>Gazebo/Black</material>
  </gazebo>
  <gazebo reference="pad">
    <material>Gazebo/FlatBlack</material>
  </gazebo>
  <gazebo reference="swivel_1">
    <material>Gazebo/Black</material>
  </gazebo>
  <gazebo reference="swivel_2">
    <material>Gazebo/Black</material>
  </gazebo>
  <gazebo reference="swivel_3">
    <material>Gazebo/Black</material>
  </gazebo>
  <gazebo reference="distal_1">
    <material>Gazebo/FlatBlack</material>
  </gazebo>
  <gazebo reference="distal_2">
    <material>Gazebo/FlatBlack</material>
  </gazebo>
  <gazebo reference="distal_3">
    <material>Gazebo/FlatBlack</material>
  </gazebo>
  <gazebo reference="distal_pad_1">
    <material>Gazebo/FlatBlack</material>
  </gazebo>
  <gazebo reference="distal_pad_2">
    <material>Gazebo/FlatBlack</material>
  </gazebo>
  <gazebo reference="distal_pad_3">
    <material>Gazebo/FlatBlack</material>
  </gazebo>
  <gazebo reference="proximal_1">
    <material>Gazebo/FlatBlack</material>
  </gazebo>
  <gazebo reference="proximal_2">
    <material>Gazebo/FlatBlack</material>
  </gazebo>
  <gazebo reference="proximal_3">
    <material>Gazebo/FlatBlack</material>
  </gazebo>
  <gazebo reference="proximal_pad_1">
    <material>Gazebo/FlatBlack</material>
  </gazebo>
  <gazebo reference="proximal_pad_2">
    <material>Gazebo/FlatBlack</material>
  </gazebo>
  <gazebo reference="proximal_pad_3">
    <material>Gazebo/FlatBlack</material>
  </gazebo>
  <gazebo reference="finger_1_flex_link">
    <material>Gazebo/YellowTransparent</material>
  </gazebo>
  <gazebo reference="finger_2_flex_link">
    <material>Gazebo/YellowTransparent</material>
  </gazebo>
  <gazebo reference="finger_3_flex_link">
    <material>Gazebo/YellowTransparent</material>
  </gazebo>
  <link name="table_link">
    <inertial>
      <origin rpy="0 0 0" xyz="0 0 0"/>
      <mass value="200"/>
      <inertia ixx="0.1" ixy="0" ixz="0" iyy="0.1" iyz="0" izz="0.1"/>
    </inertial>
    <visual>
      <origin rpy="0 0 0" xyz="0 0 0"/>
      <geometry>
        <box size="0.61 0.9125 0.59"/>
      </geometry>
      <material name="table_color">
        <color rgba="0.823529411765 0.666666666667 0.470588235294 1.0"/>
      </material>
    </visual>
    <collision>
      <origin rpy="0 0 0" xyz="0 0 0"/>
      <geometry>
        <box size="0.61 0.9125 0.59"/>
      </geometry>
    </collision>
  </link>
  <gazebo reference="table_link">
    <material>Gazebo/WoodPallet</material>
  </gazebo>
  <joint name="world_to_table_joint" type="fixed">
    <origin rpy="0 0 0" xyz="0 0 0.295"/>
    <parent link="world"/>
    <child link="table_link"/>
  </joint>
  <joint name="table_to_base_joint" type="fixed">
    <origin rpy="0 0 1.57" xyz="0 0 0.305"/>
    <parent link="table_link"/>
    <child link="base_link"/>
  </joint>
</robot>
